<?xml version="1.0" encoding="utf-8"?>
<!-- This URDF was automatically created by SolidWorks to URDF Exporter! Originally created by Stephen Brawner (brawner@gmail.com) 
     Commit Version: 1.5.1-0-g916b5db  Build Version: 1.5.7152.31018
     For more information, please see http://wiki.ros.org/sw_urdf_exporter -->
<robot
  name="robot_description">
  <link name="dummy_link">
  </link>

  <joint
    name="dummy_joint"
    type="fixed">
    <origin
      xyz="0 0 0"
      rpy="0 0 0" />
    <parent
      link="dummy_link" />
    <child
      link="base_link" />
    <axis
      xyz="0 0 1" />
  </joint>

  <link
    name="base_link">
    <inertial>
      <origin
        xyz="-0.025547 0.18996 0.0012407"
        rpy="0 0 0" />
      <mass
        value="9.2197" />
      <inertia
        ixx="0.074641"
        ixy="-0.0004252"
        ixz="2.3667E-07"
        iyy="0.064328"
        iyz="2.026E-09"
        izz="0.10813" />
    </inertial>
    <visual>
      <origin
        xyz="0 0 0"
        rpy="0 0 0" />
      <geometry>
        <mesh
          filename="package://robot_description/meshes/base_link.STL" />
      </geometry>
      <material
        name="">
        <color
          rgba="0.75294 0.75294 0.75294 1" />
      </material>
    </visual>
    <!-->
    <collision>
      <origin
        xyz="0 0 0"
        rpy="0 0 0" />
      <geometry>
        <mesh
          filename="package://robot_description/meshes/base_link.STL" />
      </geometry>
    </collision>
    <-->
  </link>
  <link
    name="wheelR">
    <inertial>
      <origin
        xyz="-1.3878E-17 -5.5511E-17 0.0254"
        rpy="0 0 0" />
      <mass
        value="0.53129" />
      <inertia
        ixx="0.0014754"
        ixy="5.421E-20"
        ixz="4.3857E-20"
        iyy="0.0014754"
        iyz="2.9588E-19"
        izz="0.0027309" />
    </inertial>
    <visual>
      <origin
        xyz="0 0 0"
        rpy="0 0 0" />
      <geometry>
        <mesh
          filename="package://robot_description/meshes/wheelR.STL" />
      </geometry>
      <material
        name="">
        <color
          rgba="0.79216 0.81961 0.93333 1" />
      </material>
    </visual>
    <collision>
      <origin
        xyz="0 0 0"
        rpy="0 0 0" />
      <geometry>
        <mesh
          filename="package://robot_description/meshes/wheelR.STL" />
      </geometry>
    </collision>
  </link>
  <joint
    name="wheelR"
    type="continuous">
    <origin
      xyz="-0.207347025920604 -0.0058042589636423 -0.433884033953984"
      rpy="1.5707963267949 -0.169516066406974 -1.5707963267949" />
    <parent
      link="base_link" />
    <child
      link="wheelR" />
    <axis
      xyz="0 0 1" />
  </joint>
  <link
    name="wheelL">
    <inertial>
      <origin
        xyz="0 5.5511E-17 -0.0254"
        rpy="0 0 0" />
      <mass
        value="0.53129" />
      <inertia
        ixx="0.0014754"
        ixy="5.421E-20"
        ixz="5.4574E-20"
        iyy="0.0014754"
        iyz="2.9588E-19"
        izz="0.0027309" />
    </inertial>
    <visual>
      <origin
        xyz="0 0 0"
        rpy="0 0 0" />
      <geometry>
        <mesh
          filename="package://robot_description/meshes/wheelL.STL" />
      </geometry>
      <material
        name="">
        <color
          rgba="0.79216 0.81961 0.93333 1" />
      </material>
    </visual>
    <collision>
      <origin
        xyz="0 0 0"
        rpy="0 0 0" />
      <geometry>
        <mesh
          filename="package://robot_description/meshes/wheelL.STL" />
      </geometry>
    </collision>
  </link>
  <joint
    name="wheelL"
    type="continuous">
    <origin
      xyz="0.148252974079396 -0.0058042589636423 -0.433884033953984"
      rpy="1.5707963267949 -0.169516066406974 -1.5707963267949" />
    <parent
      link="base_link" />
    <child
      link="wheelL" />
    <axis
      xyz="0 0 1" />
  </joint>

  <transmission name="left_motor">
    <type>transmission_interface/SimpleTransmission</type>
    <joint name="wheelL">
      <hardwareInterface>hardware_interface/EffortJointInterface</hardwareInterface>
    </joint>
    <actuator name="motor1">
      <hardwareInterface>hardware_interface/EffortJointInterface</hardwareInterface>
      <mechanicalReduction>1</mechanicalReduction>
    </actuator>
  </transmission>

  <transmission name="right_motor">
    <type>transmission_interface/SimpleTransmission</type>
    <joint name="wheelR">
      <hardwareInterface>hardware_interface/EffortJointInterface</hardwareInterface>
    </joint>
    <actuator name="motor1">
      <hardwareInterface>hardware_interface/EffortJointInterface</hardwareInterface>
      <mechanicalReduction>1</mechanicalReduction>
    </actuator>
  </transmission>

  <gazebo>
    <plugin name="gazebo_ros_control" filename="libgazebo_ros_control.so">
      <robotNamespace>/roboassistant</robotNamespace>
    </plugin>
  </gazebo>

  <gazebo reference="base_link">
    <gravity>true</gravity>
    <sensor name="imu_sensor" type="imu">
      <always_on>true</always_on>
      <update_rate>100</update_rate>
      <visualize>true</visualize>
      <topic>/roboassistant/imu</topic>
      <plugin filename="libgazebo_ros_imu_sensor.so" name="imu_plugin">
        <topicName>/roboassistant/imu</topicName>
        <bodyName>base_link</bodyName>
        <updateRateHZ>100.0</updateRateHZ>
        <gaussianNoise>0.0</gaussianNoise>
        <xyzOffset>0 0 0</xyzOffset>
        <rpyOffset>0 0 0</rpyOffset>
        <frameName>base_link</frameName>
      </plugin>
      <pose>0 0 0 0 0 0</pose>
    </sensor>
  </gazebo>
</robot>