<?xml version="1.0" encoding="utf-8"?>
<!-- This URDF was automatically created by SolidWorks to URDF Exporter! Originally created by Stephen Brawner (brawner@gmail.com) 
     Commit Version: 1.5.1-0-g916b5db  Build Version: 1.5.7152.31018
     For more information, please see http://wiki.ros.org/sw_urdf_exporter -->
<robot
  name="robot_description">


<link name="dummy_link"/>
  <joint
    name="dummy_joint"
    type="fixed">
    <origin
      xyz="0 0 0"
      rpy="0 0 0" />
    <parent
      link="dummy_link" />
    <child
      link="base_link" />
    <axis
      xyz="0 0 1" />
  </joint>


  <link
    name="base_link">
    <inertial>
    <!-- Do not know why the COM is up in the y-direction -->
      <origin
        xyz="-0.0002605 0.37184 -0.0011141" 
        rpy="0 0 0" />
      <mass
        value="4.9107" />
    <!-- Manually edited these values -->
      <inertia
        ixx="0.4438" 
        ixy="0"
        ixz="0"
        iyy="0.4659"
        iyz="0"
        izz="0.0779" />
    </inertial>
    <visual>
      <origin
        xyz="0 0 0"
        rpy="0 0 0" />
      <geometry>
        <mesh
          filename="package://robot_description/meshes/base_link.STL" />
      </geometry>
      <material
        name="">
        <color
          rgba="0.75294 0.75294 0.75294 1" />
      </material>
    </visual>
    
    <collision>
      <origin
        xyz="0 0 0"
        rpy="0 0 0" />
      <geometry>
        <mesh
          filename="package://robot_description/meshes/base_link.STL" />
      </geometry>
    </collision>
    
  </link>
  <link
    name="wheel_r">
    <inertial>
      <origin
        xyz="0.057878 -2.6487E-09 8.8445E-05"
        rpy="0 0 0" />
      <mass
        value="0.60147" />
      <inertia
        ixx="0.0021311"
        ixy="-6.6647E-11"
        ixz="-9.7953E-08"
        iyy="0.0012411"
        iyz="-1.447E-10"
        izz="0.0012419" />
    </inertial>
    <visual>
      <origin
        xyz="0 0 0"
        rpy="0 0 0" />
      <geometry>
        <mesh
          filename="package://robot_description/meshes/wheel_r.STL" />
      </geometry>
      <material
        name="">
        <color
          rgba="0.75294 0.75294 0.75294 1" />
      </material>
    </visual>
    <collision>
      <origin
        xyz="0 0 0"
        rpy="0 0 0" />
      <geometry>
        <mesh
          filename="package://robot_description/meshes/wheel_r.STL" />
      </geometry>
    </collision>
  </link>
  <joint
    name="wheel_r"
    type="continuous">
    <origin
      xyz="0.1281 0 0"
      rpy="-3.1416 0 0" />
    <parent
      link="base_link" />
    <child
      link="wheel_r" />
    <axis
      xyz="0 0 0" />
  </joint>
  <link
    name="wheel_l">
    <inertial>
      <origin
        xyz="0.057878 -2.6487E-09 8.8445E-05"
        rpy="0 0 0" />
      <mass
        value="0.60147" />
      <inertia
        ixx="0.0021311"
        ixy="-6.6647E-11"
        ixz="-9.7953E-08"
        iyy="0.0012411"
        iyz="-1.447E-10"
        izz="0.0012419" />
    </inertial>
    <visual>
      <origin
        xyz="0 0 0"
        rpy="0 0 0" />
      <geometry>
        <mesh
          filename="package://robot_description/meshes/wheel_l.STL" />
      </geometry>
      <material
        name="">
        <color
          rgba="0.75294 0.75294 0.75294 1" />
      </material>
    </visual>
    <collision>
      <origin
        xyz="0 0 0"
        rpy="0 0 0" />
      <geometry>
        <mesh
          filename="package://robot_description/meshes/wheel_l.STL" />
      </geometry>
    </collision>
  </link>
  <joint
    name="wheel_l"
    type="continuous">
    <origin
      xyz="-0.1281 0 0"
      rpy="1.5708 0 3.1416" />
    <parent
      link="base_link" />
    <child
      link="wheel_l" />
    <axis
      xyz="0 0 0" />
  </joint>
  <link
    name="camera">
    <inertial>
      <origin
        xyz="0.0002462 -6.0567E-05 -0.013048"
        rpy="0 0 0" />
      <mass
        value="0.044752" />
      <inertia
        ixx="3.9447E-06"
        ixy="-2.8014E-09"
        ixz="2.4434E-07"
        iyy="2.7362E-05"
        iyz="-1.174E-09"
        izz="2.7278E-05" />
    </inertial>
    <visual>
      <origin
        xyz="0 0 0"
        rpy="0 0 0" />
      <geometry>
        <mesh
          filename="package://robot_description/meshes/camera.STL" />
      </geometry>
      <material
        name="">
        <color
          rgba="0.79216 0.81961 0.93333 1" />
      </material>
    </visual>
    <collision>
      <origin
        xyz="0 0 0"
        rpy="0 0 0" />
      <geometry>
        <mesh
          filename="package://robot_description/meshes/camera.STL" />
      </geometry>
    </collision>
  </link>
  <joint
    name="camera"
    type="fixed">
    <origin
      xyz="0 0.12978 0.6223"
      rpy="1.5708 0 3.1416" />
    <parent
      link="base_link" />
    <child
      link="camera" />
    <axis
      xyz="0 0 0" />
  </joint>
  <link
    name="imu">
    <inertial>
      <origin
        xyz="0 0 0"
        rpy="0 0 0" />
      <mass
        value="0" />
      <inertia
        ixx="0"
        ixy="0"
        ixz="0"
        iyy="0"
        iyz="0"
        izz="0" />
    </inertial>
    <visual>
      <origin
        xyz="0 0 0"
        rpy="0 0 0" />
      <geometry>
        <mesh
          filename="package://robot_description/meshes/imu.STL" />
      </geometry>
      <material
        name="">
        <color
          rgba="1 1 1 1" />
      </material>
    </visual>
    <collision>
      <origin
        xyz="0 0 0"
        rpy="0 0 0" />
      <geometry>
        <mesh
          filename="package://robot_description/meshes/imu.STL" />
      </geometry>
    </collision>
  </link>
  <joint
    name="imu"
    type="fixed">
    <origin
      xyz="-0.0093889 -0.05715 -0.0127"
      rpy="-1.5708 0 -1.5708" />
    <parent
      link="base_link" />
    <child
      link="imu" />
    <axis
      xyz="0 0 0" />
  </joint>
</robot>