<?xml version="1.0" encoding="utf-8"?>
<!-- This URDF was automatically created by SolidWorks to URDF Exporter! Originally created by Stephen Brawner (brawner@gmail.com) 
     Commit Version: 1.5.1-0-g916b5db  Build Version: 1.5.7152.31018
     For more information, please see http://wiki.ros.org/sw_urdf_exporter -->
<robot
  name="robot_description">

  <link name="dummy_link"/>
  <joint
    name="dummy_joint"
    type="fixed">
    <origin
      xyz="0 0 0"
      rpy="0 0 0" />
    <parent
      link="dummy_link" />
    <child
      link="base_link" />
    <axis
      xyz="0 0 1" />
  </joint>

  <link
    name="base_link">
    <inertial>
      <origin
        xyz="-0.0002605 0.37184 -0.0011141"
        rpy="0 0 0" />
      <mass
        value="4.9107" />
      <inertia
        ixx="0.033566"
        ixy="-6.2188E-11"
        ixz="2.4497E-07"
        iyy="0.029042"
        iyz="3.6351E-08"
        izz="0.042561" />
    </inertial>
    <visual>
      <origin
        xyz="0 0 0"
        rpy="0 0 0" />
      <geometry>
        <mesh
          filename="package://robot_description/meshes/base_link.STL" />
      </geometry>
      <material
        name="">
        <color
          rgba="0.75294 0.75294 0.75294 1" />
      </material>
    </visual>
    <collision>
      <origin
        xyz="0 0 0"
        rpy="0 0 0" />
      <geometry>
        <mesh
          filename="package://robot_description/meshes/base_link.STL" />
      </geometry>
    </collision>
  </link>
  <link
    name="wheel_r">
    <inertial>
      <origin
        xyz="0.0578777045980548 -2.64867896708683E-09 8.84445080275366E-05"
        rpy="0 0 0" />
      <mass
        value="0.60146848738564" />
      <inertia
        ixx="0.00213114562868243"
        ixy="-6.66467766009435E-11"
        ixz="-9.79531742735922E-08"
        iyy="0.00124108974200535"
        iyz="-1.44700145504625E-10"
        izz="0.00124186405266912" />
    </inertial>
    <visual>
      <origin
        xyz="0 0 0"
        rpy="0 0 0" />
      <geometry>
        <mesh
          filename="package://robot_description/meshes/wheel_r.STL" />
      </geometry>
      <material
        name="">
        <color
          rgba="0.752941176470588 0.752941176470588 0.752941176470588 1" />
      </material>
    </visual>
    <collision>
      <origin
        xyz="0 0 0"
        rpy="0 0 0" />
      <geometry>
        <mesh
          filename="package://robot_description/meshes/wheel_r.STL" />
      </geometry>
    </collision>
  </link>
  <joint
    name="wheel_r"
    type="continuous">
    <origin
      xyz="0.1281 0 0"
      rpy="-3.1416 0 0" />
    <parent
      link="base_link" />
    <child
      link="wheel_r" />
    <axis
      xyz="0 0 0" />
  </joint>
  <link
    name="wheel_l">
    <inertial>
      <origin
        xyz="0.0578777045980547 -2.64867904017142E-09 8.84445080282169E-05"
        rpy="0 0 0" />
      <mass
        value="0.601468487385641" />
      <inertia
        ixx="0.00213114562868243"
        ixy="-6.66467763469269E-11"
        ixz="-9.79531742735019E-08"
        iyy="0.00124108974200535"
        iyz="-1.44700145434441E-10"
        izz="0.00124186405266912" />
    </inertial>
    <visual>
      <origin
        xyz="0 0 0"
        rpy="0 0 0" />
      <geometry>
        <mesh
          filename="package://robot_description/meshes/wheel_l.STL" />
      </geometry>
      <material
        name="">
        <color
          rgba="0.752941176470588 0.752941176470588 0.752941176470588 1" />
      </material>
    </visual>
    <collision>
      <origin
        xyz="0 0 0"
        rpy="0 0 0" />
      <geometry>
        <mesh
          filename="package://robot_description/meshes/wheel_l.STL" />
      </geometry>
    </collision>
  </link>
  <joint
    name="wheel_l"
    type="continuous">
    <origin
      xyz="-0.1281 0 0"
      rpy="1.5708 0 3.1416" />
    <parent
      link="base_link" />
    <child
      link="wheel_l" />
    <axis
      xyz="0 0 0" />
  </joint>
  <link
    name="camera">
    <inertial>
      <origin
        xyz="0.000246196751964501 -6.0567336562789E-05 -0.0130484997989809"
        rpy="0 0 0" />
      <mass
        value="0.0447522009688967" />
      <inertia
        ixx="3.94471808492068E-06"
        ixy="-2.8013899701667E-09"
        ixz="2.44341099254186E-07"
        iyy="2.73620912546541E-05"
        iyz="-1.17396575552847E-09"
        izz="2.72775274833281E-05" />
    </inertial>
    <visual>
      <origin
        xyz="0 0 0"
        rpy="0 0 0" />
      <geometry>
        <mesh
          filename="package://robot_description/meshes/camera.STL" />
      </geometry>
      <material
        name="">
        <color
          rgba="0.792156862745098 0.819607843137255 0.933333333333333 1" />
      </material>
    </visual>
    <collision>
      <origin
        xyz="0 0 0"
        rpy="0 0 0" />
      <geometry>
        <mesh
          filename="package://robot_description/meshes/camera.STL" />
      </geometry>
    </collision>
  </link>
  <joint
    name="camera"
    type="fixed">
    <origin
      xyz="0 0.12978 0.6223"
      rpy="1.5708 0 3.1416" />
    <parent
      link="base_link" />
    <child
      link="camera" />
    <axis
      xyz="0 0 0" />
  </joint>
  <link
    name="imu">
    <inertial>
      <origin
        xyz="0 0 0"
        rpy="0 0 0" />
      <mass
        value="0" />
      <inertia
        ixx="0"
        ixy="0"
        ixz="0"
        iyy="0"
        iyz="0"
        izz="0" />
    </inertial>
    <visual>
      <origin
        xyz="0 0 0"
        rpy="0 0 0" />
      <geometry>
        <mesh
          filename="package://robot_description/meshes/imu.STL" />
      </geometry>
      <material
        name="">
        <color
          rgba="1 1 1 1" />
      </material>
    </visual>
    <collision>
      <origin
        xyz="0 0 0"
        rpy="0 0 0" />
      <geometry>
        <mesh
          filename="package://robot_description/meshes/imu.STL" />
      </geometry>
    </collision>
  </link>
  <joint
    name="imu"
    type="fixed">
    <origin
      xyz="-0.0093889 -0.05715 -0.0127"
      rpy="-1.5708 0 -1.5708" />
    <parent
      link="base_link" />
    <child
      link="imu" />
    <axis
      xyz="0 0 0" />
  </joint>


  <!--> GAZEBO PLUGINS! <-->
  <transmission name="left_motor">
    <type>transmission_interface/SimpleTransmission</type>
    <joint name="wheel_l">
      <hardwareInterface>hardware_interface/EffortJointInterface</hardwareInterface>
    </joint>
    <actuator name="motor1">
      <hardwareInterface>hardware_interface/EffortJointInterface</hardwareInterface>
      <mechanicalReduction>1</mechanicalReduction>
    </actuator>
  </transmission>

  <transmission name="right_motor">
    <type>transmission_interface/SimpleTransmission</type>
    <joint name="wheel_r">
      <hardwareInterface>hardware_interface/EffortJointInterface</hardwareInterface>
    </joint>
    <actuator name="motor1">
      <hardwareInterface>hardware_interface/EffortJointInterface</hardwareInterface>
      <mechanicalReduction>1</mechanicalReduction>
    </actuator>
  </transmission>

  <gazebo>
    <plugin name="gazebo_ros_control" filename="libgazebo_ros_control.so">
      <robotNamespace>/controller</robotNamespace>
    </plugin>
  </gazebo>

  <gazebo reference="imu">
    <gravity>true</gravity>
    <sensor name="imu_sensor" type="imu">
      <always_on>true</always_on>
      <update_rate>300</update_rate>
      <visualize>true</visualize>
      <topic>/controller/imu</topic>
      <plugin filename="libgazebo_ros_imu_sensor.so" name="imu_plugin">
        <topicName>/controller/imu</topicName>
        <bodyName>imu</bodyName>
        <updateRateHZ>300.0</updateRateHZ>
        <gaussianNoise>0.0</gaussianNoise>
        <xyzOffset>0 0 0</xyzOffset>
        <rpyOffset>0 0 0</rpyOffset>
        <frameName>imu</frameName>
      </plugin>
      <pose>0 0 0 0 0 0</pose>
    </sensor>
  </gazebo>
</robot>