<?xml version="1.0" encoding="utf-8"?>
<!-- This URDF was automatically created by SolidWorks to URDF Exporter! Originally created by Stephen Brawner (brawner@gmail.com) 
     Commit Version: 1.5.1-0-g916b5db  Build Version: 1.5.7152.31018
     For more information, please see http://wiki.ros.org/sw_urdf_exporter -->
<robot
  name="robot_description">
  <link
    name="base_link">
    <inertial>
      <origin
        xyz="-0.024056 0.21306 -0.00086703"
        rpy="0 0 0" />
      <mass
        value="6.7886" />
      <inertia
        ixx="0.071127"
        ixy="-0.00042515"
        ixz="2.4622E-07"
        iyy="0.049245"
        iyz="4.8155E-09"
        izz="0.095082" />
    </inertial>
    <visual>
      <origin
        xyz="0 0 0"
        rpy="0 0 0" />
      <geometry>
        <mesh
          filename="package://robot_description/meshes/base_link.STL" />
      </geometry>
      <material
        name="">
        <color
          rgba="0.75294 0.75294 0.75294 1" />
      </material>
    </visual>
    <collision>
      <origin
        xyz="0 0 0"
        rpy="0 0 0" />
      <geometry>
        <mesh
          filename="package://robot_description/meshes/base_link.STL" />
      </geometry>
    </collision>
  </link>
  <link
    name="left_wheel">
    <inertial>
      <origin
        xyz="-0.1779 -2.4425E-05 9.6955E-05"
        rpy="0 0 0" />
      <mass
        value="0.53579" />
      <inertia
        ixx="0.0027072"
        ixy="4.5959E-08"
        ixz="-8.9443E-08"
        iyy="0.0014654"
        iyz="-1.8453E-07"
        izz="0.0014661" />
    </inertial>
    <visual>
      <origin
        xyz="0 0 0"
        rpy="0 0 0" />
      <geometry>
        <mesh
          filename="package://robot_description/meshes/left_wheel.STL" />
      </geometry>
      <material
        name="">
        <color
          rgba="0.75294 0.75294 0.75294 1" />
      </material>
    </visual>
    <collision>
      <origin
        xyz="0 0 0"
        rpy="0 0 0" />
      <geometry>
        <mesh
          filename="package://robot_description/meshes/left_wheel.STL" />
      </geometry>
    </collision>
  </link>
  <joint
    name="left wheel"
    type="continuous">
    <origin
      xyz="-0.067076 -0.0058043 -0.43388"
      rpy="1.5231 0 0" />
    <parent
      link="base_link" />
    <child
      link="left_wheel" />
    <axis
      xyz="1 0 0" />
  </joint>
  <link
    name="right_wheel">
    <inertial>
      <origin
        xyz="-0.1779 -2.4425E-05 9.6955E-05"
        rpy="0 0 0" />
      <mass
        value="0.53579" />
      <inertia
        ixx="0.0027072"
        ixy="4.5959E-08"
        ixz="-8.9443E-08"
        iyy="0.0014654"
        iyz="-1.8453E-07"
        izz="0.0014661" />
    </inertial>
    <visual>
      <origin
        xyz="0 0 0"
        rpy="0 0 0" />
      <geometry>
        <mesh
          filename="package://robot_description/meshes/right_wheel.STL" />
      </geometry>
      <material
        name="">
        <color
          rgba="0.75294 0.75294 0.75294 1" />
      </material>
    </visual>
    <collision>
      <origin
        xyz="0 0 0"
        rpy="0 0 0" />
      <geometry>
        <mesh
          filename="package://robot_description/meshes/right_wheel.STL" />
      </geometry>
    </collision>
  </link>
  <joint
    name="right_wheel"
    type="continuous">
    <origin
      xyz="0.0079815 -0.0058043 -0.43388"
      rpy="1.983 0 3.1416" />
    <parent
      link="base_link" />
    <child
      link="right_wheel" />
    <axis
      xyz="1 0 0" />
  </joint>
  <link
    name="stationary_shaft">
    <inertial>
      <origin
        xyz="0 0 0"
        rpy="0 0 0" />
      <mass
        value="0" />
      <inertia
        ixx="0"
        ixy="0"
        ixz="0"
        iyy="0"
        iyz="0"
        izz="0" />
    </inertial>
    <visual>
      <origin
        xyz="0 0 0"
        rpy="0 0 0" />
      <geometry>
        <mesh
          filename="package://robot_description/meshes/stationary_shaft.STL" />
      </geometry>
      <material
        name="">
        <color
          rgba="1 1 1 1" />
      </material>
    </visual>
    <collision>
      <origin
        xyz="0 0 0"
        rpy="0 0 0" />
      <geometry>
        <mesh
          filename="package://robot_description/meshes/stationary_shaft.STL" />
      </geometry>
    </collision>
  </link>
  <joint
    name="stationary_shaft"
    type="continuous">
    <origin
      xyz="0 0 0"
      rpy="1.5708 0.3143 -1.5708" />
    <parent
      link="base_link" />
    <child
      link="stationary_shaft" />
    <axis
      xyz="0 0 1" />
  </joint>
</robot>